<?xml version="1.0"?>
<robot name="humanoid">

  <!-- Base Link (Torso) -->
  <link name="base_link">
    <visual>
      <geometry>
        <box size="0.2 0.3 0.4"/>
      </geometry>
      <material name="grey">
        <color rgba="0.5 0.5 0.5 1"/>
      </material>
    </visual>
  </link>

  <!-- Head (1 DOF) -->
  <link name="head_link">
    <visual>
      <geometry>
        <sphere radius="0.1"/>
      </geometry>
      <material name="white">
        <color rgba="1 1 1 1"/>
      </material>
    </visual>
  </link>
  <joint name="head_pan_joint" type="revolute">
    <parent link="base_link"/>
    <child link="head_link"/>
    <origin xyz="0 0 0.25" rpy="0 0 0"/>
    <axis xyz="0 0 1"/>
    <limit lower="-1.57" upper="1.57" effort="10" velocity="1.0"/>
  </joint>

  <!-- Left Arm (3 DOF) -->
  <link name="left_shoulder_link">
    <visual>
      <geometry>
        <sphere radius="0.05"/>
      </geometry>
      <material name="blue">
        <color rgba="0 0 0.8 1"/>
      </material>
    </visual>
  </link>
  <joint name="left_shoulder_pan_joint" type="revolute">
    <parent link="base_link"/>
    <child link="left_shoulder_link"/>
    <origin xyz="0 0.2 0.15" rpy="0 0 0"/>
    <axis xyz="0 1 0"/>
    <limit lower="-1.57" upper="1.57" effort="10" velocity="1.0"/>
  </joint>

  <link name="left_upper_arm_link">
    <visual>
      <geometry>
        <box size="0.25 0.05 0.05"/>
      </geometry>
      <material name="blue"/>
    </visual>
  </link>
  <joint name="left_shoulder_pitch_joint" type="revolute">
    <parent link="left_shoulder_link"/>
    <child link="left_upper_arm_link"/>
    <origin xyz="0.125 0 0" rpy="0 0 0"/>
    <axis xyz="0 0 1"/>
    <limit lower="-1.57" upper="1.57" effort="10" velocity="1.0"/>
  </joint>

  <link name="left_lower_arm_link">
    <visual>
      <geometry>
        <box size="0.25 0.05 0.05"/>
      </geometry>
      <material name="white"/>
    </visual>
  </link>
  <joint name="left_elbow_pitch_joint" type="revolute">
    <parent link="left_upper_arm_link"/>
    <child link="left_lower_arm_link"/>
    <origin xyz="0.125 0 0" rpy="0 0 0"/>
    <axis xyz="0 0 1"/>
    <limit lower="0" upper="1.57" effort="10" velocity="1.0"/>
  </joint>

  <!-- Right Arm (3 DOF) -->
  <link name="right_shoulder_link">
    <visual>
      <geometry>
        <sphere radius="0.05"/>
      </geometry>
      <material name="blue"/>
    </visual>
  </link>
  <joint name="right_shoulder_pan_joint" type="revolute">
    <parent link="base_link"/>
    <child link="right_shoulder_link"/>
    <origin xyz="0 -0.2 0.15" rpy="0 0 0"/>
    <axis xyz="0 1 0"/>
    <limit lower="-1.57" upper="1.57" effort="10" velocity="1.0"/>
  </joint>

  <link name="right_upper_arm_link">
    <visual>
      <geometry>
        <box size="0.25 0.05 0.05"/>
      </geometry>
      <material name="blue"/>
    </visual>
  </link>
  <joint name="right_shoulder_pitch_joint" type="revolute">
    <parent link="right_shoulder_link"/>
    <child link="right_upper_arm_link"/>
    <origin xyz="0.125 0 0" rpy="0 0 0"/>
    <axis xyz="0 0 1"/>
    <limit lower="-1.57" upper="1.57" effort="10" velocity="1.0"/>
  </joint>

  <link name="right_lower_arm_link">
    <visual>
      <geometry>
        <box size="0.25 0.05 0.05"/>
      </geometry>
      <material name="white"/>
    </visual>
  </link>
  <joint name="right_elbow_pitch_joint" type="revolute">
    <parent link="right_upper_arm_link"/>
    <child link="right_lower_arm_link"/>
    <origin xyz="0.125 0 0" rpy="0 0 0"/>
    <axis xyz="0 0 1"/>
    <limit lower="0" upper="1.57" effort="10" velocity="1.0"/>
  </joint>

  <!-- Left Leg (4 DOF) -->
  <link name="left_hip_link">
    <visual>
      <geometry>
        <sphere radius="0.06"/>
      </geometry>
      <material name="blue"/>
    </visual>
  </link>
  <joint name="left_hip_pan_joint" type="revolute">
    <parent link="base_link"/>
    <child link="left_hip_link"/>
    <origin xyz="0 0.1 -0.25" rpy="0 0 0"/>
    <axis xyz="0 0 1"/>
    <limit lower="-0.785" upper="0.785" effort="10" velocity="1.0"/>
  </joint>

  <link name="left_thigh_link">
    <visual>
      <geometry>
        <box size="0.06 0.06 0.3"/>
      </geometry>
      <material name="blue"/>
    </visual>
  </link>
  <joint name="left_hip_pitch_joint" type="revolute">
    <parent link="left_hip_link"/>
    <child link="left_thigh_link"/>
    <origin xyz="0 0 -0.15" rpy="0 0 0"/>
    <axis xyz="0 1 0"/>
    <limit lower="-1.57" upper="1.57" effort="10" velocity="1.0"/>
  </joint>

  <link name="left_shin_link">
    <visual>
      <geometry>
        <box size="0.06 0.06 0.3"/>
      </geometry>
      <material name="white"/>
    </visual>
  </link>
  <joint name="left_knee_pitch_joint" type="revolute">
    <parent link="left_thigh_link"/>
    <child link="left_shin_link"/>
    <origin xyz="0 0 -0.15" rpy="0 0 0"/>
    <axis xyz="0 1 0"/>
    <limit lower="0" upper="1.57" effort="10" velocity="1.0"/>
  </joint>

  <link name="left_foot_link">
    <visual>
      <geometry>
        <box size="0.15 0.1 0.04"/>
      </geometry>
      <material name="grey"/>
    </visual>
  </link>
  <joint name="left_ankle_pitch_joint" type="revolute">
    <parent link="left_shin_link"/>
    <child link="left_foot_link"/>
    <origin xyz="0 0 -0.17" rpy="0 0 0"/>
    <axis xyz="0 1 0"/>
    <limit lower="-0.785" upper="0.785" effort="10" velocity="1.0"/>
  </joint>

  <!-- Right Leg (4 DOF) -->
  <link name="right_hip_link">
    <visual>
      <geometry>
        <sphere radius="0.06"/>
      </geometry>
      <material name="blue"/>
    </visual>
  </link>
  <joint name="right_hip_pan_joint" type="revolute">
    <parent link="base_link"/>
    <child link="right_hip_link"/>
    <origin xyz="0 -0.1 -0.25" rpy="0 0 0"/>
    <axis xyz="0 0 1"/>
    <limit lower="-0.785" upper="0.785" effort="10" velocity="1.0"/>
  </joint>

  <link name="right_thigh_link">
    <visual>
      <geometry>
        <box size="0.06 0.06 0.3"/>
      </geometry>
      <material name="blue"/>
    </visual>
  </link>
  <joint name="right_hip_pitch_joint" type="revolute">
    <parent link="right_hip_link"/>
    <child link="right_thigh_link"/>
    <origin xyz="0 0 -0.15" rpy="0 0 0"/>
    <axis xyz="0 1 0"/>
    <limit lower="-1.57" upper="1.57" effort="10" velocity="1.0"/>
  </joint>

  <link name="right_shin_link">
    <visual>
      <geometry>
        <box size="0.06 0.06 0.3"/>
      </geometry>
      <material name="white"/>
    </visual>
  </link>
  <joint name="right_knee_pitch_joint" type="revolute">
    <parent link="right_thigh_link"/>
    <child link="right_shin_link"/>
    <origin xyz="0 0 -0.15" rpy="0 0 0"/>
    <axis xyz="0 1 0"/>
    <limit lower="0" upper="1.57" effort="10" velocity="1.0"/>
  </joint>

  <link name="right_foot_link">
    <visual>
      <geometry>
        <box size="0.15 0.1 0.04"/>
      </geometry>
      <material name="grey"/>
    </visual>
  </link>
  <joint name="right_ankle_pitch_joint" type="revolute">
    <parent link="right_shin_link"/>
    <child link="right_foot_link"/>
    <origin xyz="0 0 -0.17" rpy="0 0 0"/>
    <axis xyz="0 1 0"/>
    <limit lower="-0.785" upper="0.785" effort="10" velocity="1.0"/>
  </joint>

  <!-- ========== CART SYSTEM (Tethered Support Platform) ========== -->

  <!-- Cart Base Platform (25cm x 25cm red platform) -->
  <link name="cart_base_link">
    <visual>
      <geometry>
        <box size="0.25 0.25 0.02"/>
      </geometry>
      <origin xyz="0 0 0.01" rpy="0 0 0"/>
      <material name="red">
        <color rgba="0.8 0.1 0.1 1"/>
      </material>
    </visual>
    <collision>
      <geometry>
        <box size="0.25 0.25 0.02"/>
      </geometry>
      <origin xyz="0 0 0.01" rpy="0 0 0"/>
    </collision>
    <inertial>
      <mass value="2.0"/>
      <origin xyz="0 0 0.01" rpy="0 0 0"/>
      <inertia ixx="0.0208" ixy="0.0" ixz="0.0" iyy="0.0208" iyz="0.0" izz="0.0417"/>
    </inertial>
  </link>

  <!-- Elastic String Connection (Fixed) -->
  <!-- Connects robot waist to cart - cart is passive support, not controlled -->
  <joint name="cart_tether_joint" type="fixed">
    <parent link="base_link"/>
    <child link="cart_base_link"/>
    <!-- Position cart 10cm behind robot at waist level (base_link center = 0) -->
    <!-- Cart is lower than robot, so offset in Z to put it on ground level -->
    <origin xyz="-0.15 0 -0.65" rpy="0 0 0"/>
  </joint>

  <!-- Electronics Platform (upper deck) -->
  <link name="electronics_platform_link">
    <visual>
      <geometry>
        <box size="0.24 0.24 0.02"/>
      </geometry>
      <origin xyz="0 0 0.025" rpy="0 0 0"/>
      <material name="white">
        <color rgba="0.9 0.9 0.9 1"/>
      </material>
    </visual>
    <collision>
      <geometry>
        <box size="0.24 0.24 0.02"/>
      </geometry>
      <origin xyz="0 0 0.025" rpy="0 0 0"/>
    </collision>
    <inertial>
      <mass value="0.5"/>
      <origin xyz="0 0 0.025" rpy="0 0 0"/>
      <inertia ixx="0.0024" ixy="0.0" ixz="0.0" iyy="0.0024" iyz="0.0" izz="0.0048"/>
    </inertial>
  </link>

  <joint name="electronics_platform_joint" type="fixed">
    <parent link="cart_base_link"/>
    <child link="electronics_platform_link"/>
    <origin xyz="0 0 0.05" rpy="0 0 0"/>
  </joint>

  <!-- 16 Wheels: 4 corners × 4 wheels each -->
  <!-- Front Left Corner (4 wheels) -->
  <link name="wheel_fl_1">
    <visual>
      <geometry>
        <cylinder radius="0.015" length="0.01"/>
      </geometry>
      <origin xyz="0 0 0" rpy="1.5708 0 0"/>
      <material name="black">
        <color rgba="0.1 0.1 0.1 1"/>
      </material>
    </visual>
    <collision>
      <geometry>
        <cylinder radius="0.015" length="0.01"/>
      </geometry>
      <origin xyz="0 0 0" rpy="1.5708 0 0"/>
    </collision>
    <inertial>
      <mass value="0.05"/>
      <inertia ixx="0.00001" ixy="0" ixz="0" iyy="0.00001" iyz="0" izz="0.00001"/>
    </inertial>
  </link>
  <joint name="wheel_fl_1_joint" type="fixed">
    <parent link="cart_base_link"/>
    <child link="wheel_fl_1"/>
    <origin xyz="0.11 0.11 -0.01" rpy="0 0 0"/>
  </joint>

  <link name="wheel_fl_2">
    <visual>
      <geometry>
        <cylinder radius="0.015" length="0.01"/>
      </geometry>
      <origin xyz="0 0 0" rpy="1.5708 0 0"/>
      <material name="black"/>
    </visual>
    <collision>
      <geometry>
        <cylinder radius="0.015" length="0.01"/>
      </geometry>
      <origin xyz="0 0 0" rpy="1.5708 0 0"/>
    </collision>
    <inertial>
      <mass value="0.05"/>
      <inertia ixx="0.00001" ixy="0" ixz="0" iyy="0.00001" iyz="0" izz="0.00001"/>
    </inertial>
  </link>
  <joint name="wheel_fl_2_joint" type="fixed">
    <parent link="cart_base_link"/>
    <child link="wheel_fl_2"/>
    <origin xyz="0.13 0.11 -0.01" rpy="0 0 0"/>
  </joint>

  <link name="wheel_fl_3">
    <visual>
      <geometry>
        <cylinder radius="0.015" length="0.01"/>
      </geometry>
      <origin xyz="0 0 0" rpy="1.5708 0 0"/>
      <material name="black"/>
    </visual>
    <collision>
      <geometry>
        <cylinder radius="0.015" length="0.01"/>
      </geometry>
      <origin xyz="0 0 0" rpy="1.5708 0 0"/>
    </collision>
    <inertial>
      <mass value="0.05"/>
      <inertia ixx="0.00001" ixy="0" ixz="0" iyy="0.00001" iyz="0" izz="0.00001"/>
    </inertial>
  </link>
  <joint name="wheel_fl_3_joint" type="fixed">
    <parent link="cart_base_link"/>
    <child link="wheel_fl_3"/>
    <origin xyz="0.11 0.13 -0.01" rpy="0 0 0"/>
  </joint>

  <link name="wheel_fl_4">
    <visual>
      <geometry>
        <cylinder radius="0.015" length="0.01"/>
      </geometry>
      <origin xyz="0 0 0" rpy="1.5708 0 0"/>
      <material name="black"/>
    </visual>
    <collision>
      <geometry>
        <cylinder radius="0.015" length="0.01"/>
      </geometry>
      <origin xyz="0 0 0" rpy="1.5708 0 0"/>
    </collision>
    <inertial>
      <mass value="0.05"/>
      <inertia ixx="0.00001" ixy="0" ixz="0" iyy="0.00001" iyz="0" izz="0.00001"/>
    </inertial>
  </link>
  <joint name="wheel_fl_4_joint" type="fixed">
    <parent link="cart_base_link"/>
    <child link="wheel_fl_4"/>
    <origin xyz="0.13 0.13 -0.01" rpy="0 0 0"/>
  </joint>

  <!-- Front Right Corner (4 wheels) -->
  <link name="wheel_fr_1">
    <visual>
      <geometry>
        <cylinder radius="0.015" length="0.01"/>
      </geometry>
      <origin xyz="0 0 0" rpy="1.5708 0 0"/>
      <material name="black"/>
    </visual>
    <collision>
      <geometry>
        <cylinder radius="0.015" length="0.01"/>
      </geometry>
      <origin xyz="0 0 0" rpy="1.5708 0 0"/>
    </collision>
    <inertial>
      <mass value="0.05"/>
      <inertia ixx="0.00001" ixy="0" ixz="0" iyy="0.00001" iyz="0" izz="0.00001"/>
    </inertial>
  </link>
  <joint name="wheel_fr_1_joint" type="fixed">
    <parent link="cart_base_link"/>
    <child link="wheel_fr_1"/>
    <origin xyz="0.11 -0.11 -0.01" rpy="0 0 0"/>
  </joint>

  <link name="wheel_fr_2">
    <visual>
      <geometry>
        <cylinder radius="0.015" length="0.01"/>
      </geometry>
      <origin xyz="0 0 0" rpy="1.5708 0 0"/>
      <material name="black"/>
    </visual>
    <collision>
      <geometry>
        <cylinder radius="0.015" length="0.01"/>
      </geometry>
      <origin xyz="0 0 0" rpy="1.5708 0 0"/>
    </collision>
    <inertial>
      <mass value="0.05"/>
      <inertia ixx="0.00001" ixy="0" ixz="0" iyy="0.00001" iyz="0" izz="0.00001"/>
    </inertial>
  </link>
  <joint name="wheel_fr_2_joint" type="fixed">
    <parent link="cart_base_link"/>
    <child link="wheel_fr_2"/>
    <origin xyz="0.13 -0.11 -0.01" rpy="0 0 0"/>
  </joint>

  <link name="wheel_fr_3">
    <visual>
      <geometry>
        <cylinder radius="0.015" length="0.01"/>
      </geometry>
      <origin xyz="0 0 0" rpy="1.5708 0 0"/>
      <material name="black"/>
    </visual>
    <collision>
      <geometry>
        <cylinder radius="0.015" length="0.01"/>
      </geometry>
      <origin xyz="0 0 0" rpy="1.5708 0 0"/>
    </collision>
    <inertial>
      <mass value="0.05"/>
      <inertia ixx="0.00001" ixy="0" ixz="0" iyy="0.00001" iyz="0" izz="0.00001"/>
    </inertial>
  </link>
  <joint name="wheel_fr_3_joint" type="fixed">
    <parent link="cart_base_link"/>
    <child link="wheel_fr_3"/>
    <origin xyz="0.11 -0.13 -0.01" rpy="0 0 0"/>
  </joint>

  <link name="wheel_fr_4">
    <visual>
      <geometry>
        <cylinder radius="0.015" length="0.01"/>
      </geometry>
      <origin xyz="0 0 0" rpy="1.5708 0 0"/>
      <material name="black"/>
    </visual>
    <collision>
      <geometry>
        <cylinder radius="0.015" length="0.01"/>
      </geometry>
      <origin xyz="0 0 0" rpy="1.5708 0 0"/>
    </collision>
    <inertial>
      <mass value="0.05"/>
      <inertia ixx="0.00001" ixy="0" ixz="0" iyy="0.00001" iyz="0" izz="0.00001"/>
    </inertial>
  </link>
  <joint name="wheel_fr_4_joint" type="fixed">
    <parent link="cart_base_link"/>
    <child link="wheel_fr_4"/>
    <origin xyz="0.13 -0.13 -0.01" rpy="0 0 0"/>
  </joint>

  <!-- Back Left Corner (4 wheels) -->
  <link name="wheel_bl_1">
    <visual>
      <geometry>
        <cylinder radius="0.015" length="0.01"/>
      </geometry>
      <origin xyz="0 0 0" rpy="1.5708 0 0"/>
      <material name="black"/>
    </visual>
    <collision>
      <geometry>
        <cylinder radius="0.015" length="0.01"/>
      </geometry>
      <origin xyz="0 0 0" rpy="1.5708 0 0"/>
    </collision>
    <inertial>
      <mass value="0.05"/>
      <inertia ixx="0.00001" ixy="0" ixz="0" iyy="0.00001" iyz="0" izz="0.00001"/>
    </inertial>
  </link>
  <joint name="wheel_bl_1_joint" type="fixed">
    <parent link="cart_base_link"/>
    <child link="wheel_bl_1"/>
    <origin xyz="-0.11 0.11 -0.01" rpy="0 0 0"/>
  </joint>

  <link name="wheel_bl_2">
    <visual>
      <geometry>
        <cylinder radius="0.015" length="0.01"/>
      </geometry>
      <origin xyz="0 0 0" rpy="1.5708 0 0"/>
      <material name="black"/>
    </visual>
    <collision>
      <geometry>
        <cylinder radius="0.015" length="0.01"/>
      </geometry>
      <origin xyz="0 0 0" rpy="1.5708 0 0"/>
    </collision>
    <inertial>
      <mass value="0.05"/>
      <inertia ixx="0.00001" ixy="0" ixz="0" iyy="0.00001" iyz="0" izz="0.00001"/>
    </inertial>
  </link>
  <joint name="wheel_bl_2_joint" type="fixed">
    <parent link="cart_base_link"/>
    <child link="wheel_bl_2"/>
    <origin xyz="-0.13 0.11 -0.01" rpy="0 0 0"/>
  </joint>

  <link name="wheel_bl_3">
    <visual>
      <geometry>
        <cylinder radius="0.015" length="0.01"/>
      </geometry>
      <origin xyz="0 0 0" rpy="1.5708 0 0"/>
      <material name="black"/>
    </visual>
    <collision>
      <geometry>
        <cylinder radius="0.015" length="0.01"/>
      </geometry>
      <origin xyz="0 0 0" rpy="1.5708 0 0"/>
    </collision>
    <inertial>
      <mass value="0.05"/>
      <inertia ixx="0.00001" ixy="0" ixz="0" iyy="0.00001" iyz="0" izz="0.00001"/>
    </inertial>
  </link>
  <joint name="wheel_bl_3_joint" type="fixed">
    <parent link="cart_base_link"/>
    <child link="wheel_bl_3"/>
    <origin xyz="-0.11 0.13 -0.01" rpy="0 0 0"/>
  </joint>

  <link name="wheel_bl_4">
    <visual>
      <geometry>
        <cylinder radius="0.015" length="0.01"/>
      </geometry>
      <origin xyz="0 0 0" rpy="1.5708 0 0"/>
      <material name="black"/>
    </visual>
    <collision>
      <geometry>
        <cylinder radius="0.015" length="0.01"/>
      </geometry>
      <origin xyz="0 0 0" rpy="1.5708 0 0"/>
    </collision>
    <inertial>
      <mass value="0.05"/>
      <inertia ixx="0.00001" ixy="0" ixz="0" iyy="0.00001" iyz="0" izz="0.00001"/>
    </inertial>
  </link>
  <joint name="wheel_bl_4_joint" type="fixed">
    <parent link="cart_base_link"/>
    <child link="wheel_bl_4"/>
    <origin xyz="-0.13 0.13 -0.01" rpy="0 0 0"/>
  </joint>

  <!-- Back Right Corner (4 wheels) -->
  <link name="wheel_br_1">
    <visual>
      <geometry>
        <cylinder radius="0.015" length="0.01"/>
      </geometry>
      <origin xyz="0 0 0" rpy="1.5708 0 0"/>
      <material name="black"/>
    </visual>
    <collision>
      <geometry>
        <cylinder radius="0.015" length="0.01"/>
      </geometry>
      <origin xyz="0 0 0" rpy="1.5708 0 0"/>
    </collision>
    <inertial>
      <mass value="0.05"/>
      <inertia ixx="0.00001" ixy="0" ixz="0" iyy="0.00001" iyz="0" izz="0.00001"/>
    </inertial>
  </link>
  <joint name="wheel_br_1_joint" type="fixed">
    <parent link="cart_base_link"/>
    <child link="wheel_br_1"/>
    <origin xyz="-0.11 -0.11 -0.01" rpy="0 0 0"/>
  </joint>

  <link name="wheel_br_2">
    <visual>
      <geometry>
        <cylinder radius="0.015" length="0.01"/>
      </geometry>
      <origin xyz="0 0 0" rpy="1.5708 0 0"/>
      <material name="black"/>
    </visual>
    <collision>
      <geometry>
        <cylinder radius="0.015" length="0.01"/>
      </geometry>
      <origin xyz="0 0 0" rpy="1.5708 0 0"/>
    </collision>
    <inertial>
      <mass value="0.05"/>
      <inertia ixx="0.00001" ixy="0" ixz="0" iyy="0.00001" iyz="0" izz="0.00001"/>
    </inertial>
  </link>
  <joint name="wheel_br_2_joint" type="fixed">
    <parent link="cart_base_link"/>
    <child link="wheel_br_2"/>
    <origin xyz="-0.13 -0.11 -0.01" rpy="0 0 0"/>
  </joint>

  <link name="wheel_br_3">
    <visual>
      <geometry>
        <cylinder radius="0.015" length="0.01"/>
      </geometry>
      <origin xyz="0 0 0" rpy="1.5708 0 0"/>
      <material name="black"/>
    </visual>
    <collision>
      <geometry>
        <cylinder radius="0.015" length="0.01"/>
      </geometry>
      <origin xyz="0 0 0" rpy="1.5708 0 0"/>
    </collision>
    <inertial>
      <mass value="0.05"/>
      <inertia ixx="0.00001" ixy="0" ixz="0" iyy="0.00001" iyz="0" izz="0.00001"/>
    </inertial>
  </link>
  <joint name="wheel_br_3_joint" type="fixed">
    <parent link="cart_base_link"/>
    <child link="wheel_br_3"/>
    <origin xyz="-0.11 -0.13 -0.01" rpy="0 0 0"/>
  </joint>

  <link name="wheel_br_4">
    <visual>
      <geometry>
        <cylinder radius="0.015" length="0.01"/>
      </geometry>
      <origin xyz="0 0 0" rpy="1.5708 0 0"/>
      <material name="black"/>
    </visual>
    <collision>
      <geometry>
        <cylinder radius="0.015" length="0.01"/>
      </geometry>
      <origin xyz="0 0 0" rpy="1.5708 0 0"/>
    </collision>
    <inertial>
      <mass value="0.05"/>
      <inertia ixx="0.00001" ixy="0" ixz="0" iyy="0.00001" iyz="0" izz="0.00001"/>
    </inertial>
  </link>
  <joint name="wheel_br_4_joint" type="fixed">
    <parent link="cart_base_link"/>
    <child link="wheel_br_4"/>
    <origin xyz="-0.13 -0.13 -0.01" rpy="0 0 0"/>
  </joint>

</robot>
